<?xml version="1.0"?>
<robot xmlns:xacro="http://www.ros.org/wiki/xacro" name="mobi">

  <!-- ========================================================================================================================================== -->
  <!-- Variables -->

  <xacro:property name="chassis_width" value="0.2" />
  <xacro:property name="chassis_length" value="0.3" />
  <xacro:property name="chassis_height" value="0.08" />

  <xacro:property name="body_width" value="0.15" />
  <xacro:property name="body_length" value="0.2" />
  <xacro:property name="body_height" value="0.07" />

  <xacro:property name="top_plate_distance" value="0.11" />

  <xacro:property name="wheel_diameter" value="0.0375" />
  <xacro:property name="wheel_thickness" value="0.035" />
  <!-- gap between chassis and wheel -->
  <xacro:property name="wheel_gap" value="0.01" />
  <!-- distance between the wheel centers. wheels are spaced evenly -->
  <xacro:property name="wheel_distance" value="0.25" />
  <!-- wheel offset from the chassis center -->
  <xacro:property name="wheel_offset_z" value="-0.025" />

  <!-- ========================================================================================================================================== -->
  <!-- Colors -->

  <material name="blue">
    <color rgba="0 0 0.8 1"/>
  </material>

  <material name="yellow">
    <color rgba="1 1 0 1"/>
  </material>

  <material name="gray">
    <color rgba="0.8 0.8 0.8 1"/>
  </material>

  <!-- ========================================================================================================================================== -->
  <!-- Gemoetry -->

  <link name="base_link">
  </link>

  <link name="chassis">
    <visual>
      <geometry>
        <box size="${chassis_width} ${chassis_length} ${chassis_height}"/>
      </geometry>
      <origin rpy="0 0 0" xyz="0 0 0"/>
      <material name="yellow"/>
    </visual>
  </link>

  <joint name="chassis_joint" type="fixed">
    <parent link="base_link"/>
    <child link="chassis"/>
    <origin rpy="0 0 0" xyz="0 0 ${-wheel_offset_z}"/>
  </joint>

  <link name="body">
    <visual>
      <geometry>
        <!-- <box size="0.17 0.2 0.07"/> -->
        <mesh filename="package://mobi_rviz/meshes/Housing_v54.stl" scale="0.001 0.001 0.001" />
      </geometry>
      <material name="gray"/>
      <origin rpy="0 0 ${pi / 2}" xyz="${-body_width / 2} ${body_length / 2} ${-body_height / 2}"/>
    </visual>
  </link>

  <joint name="body_joint" type="fixed">
    <parent link="chassis"/>
    <child link="body"/>
    <origin rpy="0 0 0" xyz="0 0 ${chassis_height / 2 + body_height / 2}"/>
  </joint>

  <link name="top_plate">
    <visual>
      <geometry>
        <!-- <box size="0.15 0.15 0.02"/> -->
        <mesh filename="package://mobi_rviz/meshes/msb15_m-step.stl" scale="0.001 0.001 0.001" />
      </geometry>
      <origin rpy="${pi / 2} 0 0" xyz="0 0 0"/>
    </visual>
  </link>

  <joint name="top_plate_joint" type="fixed">
    <parent link="body"/>
    <child link="top_plate"/>
    <origin rpy="0 0 0" xyz="0 0 ${top_plate_distance}"/>
  </joint>

  <!-- ========================================================================================================================================== -->
  <!-- Wheels -->

  <link name="front_right_wheel">
    <visual>
      <geometry>
        <cylinder length="${wheel_thickness}" radius="${wheel_diameter}"/>
      </geometry>
      <material name="blue"/>
    </visual>
  </link>

  <joint name="front_right_wheel_joint" type="continuous">
    <parent link="chassis"/>
    <child link="front_right_wheel"/>
    <origin xyz="${chassis_width / 2 + wheel_thickness / 2 + wheel_gap} ${wheel_distance / 2} ${wheel_offset_z}" rpy="${pi/2} 0 ${pi/2}"/>
    <axis xyz="0 0 -1"/>
  </joint>

  <link name="front_left_wheel">
    <visual>
      <geometry>
        <cylinder length="${wheel_thickness}" radius="${wheel_diameter}"/>
      </geometry>
      <material name="blue"/>
    </visual>
  </link>

  <joint name="front_left_wheel_joint" type="continuous">
    <parent link="chassis"/>
    <child link="front_left_wheel"/>
    <origin xyz="${-(chassis_width / 2 + wheel_thickness / 2 + wheel_gap)} ${wheel_distance / 2} ${wheel_offset_z}" rpy="${-pi/2} 0 ${pi/2}"/>
    <axis xyz="0 0 1"/>
  </joint>

  <link name="rear_right_wheel">
    <visual>
      <geometry>
        <cylinder length="${wheel_thickness}" radius="${wheel_diameter}"/>
      </geometry>
      <material name="blue"/>
    </visual>
  </link>

  <joint name="rear_right_wheel_joint" type="continuous">
    <parent link="chassis"/>
    <child link="rear_right_wheel"/>
    <origin xyz="${chassis_width / 2 + wheel_thickness / 2 + wheel_gap} ${-wheel_distance / 2} ${wheel_offset_z}" rpy="${pi/2} 0 ${pi/2}"/>
    <axis xyz="0 0 -1"/>
  </joint>

  <link name="rear_left_wheel">
    <visual>
      <geometry>
        <cylinder length="${wheel_thickness}" radius="${wheel_diameter}"/>
      </geometry>
      <material name="blue"/>
    </visual>
  </link>

  <joint name="rear_left_wheel_joint" type="continuous">
    <parent link="chassis"/>
    <child link="rear_left_wheel"/>
    <origin xyz="${-(chassis_width / 2 + wheel_thickness / 2 + wheel_gap)} ${-wheel_distance / 2} ${wheel_offset_z}" rpy="${-pi/2} 0 ${pi/2}"/>
    <axis xyz="0 0 1"/>
  </joint>

  <!-- ========================================================================================================================================== -->
  <!-- Sensors  -->

  <link name="lidar">
    <!-- <visual>
      <origin rpy="0 0 0" xyz="0 0 0"/>
    </visual> -->
  </link>

  <joint name="lidar_joint" type="fixed">
    <parent link="top_plate"/>
    <child link="lidar"/>
    <origin rpy="0 0 ${pi/2}" xyz="0 0 0.045"/>
  </joint>

</robot>
