<?xml version="1.0"?>
<robot name="mobi">

  <material name="blue">
    <color rgba="0 0 0.8 1"/>
  </material>

  <material name="yellow">
    <color rgba="1 1 0 1"/>
  </material>

  <material name="gray">
    <color rgba="0.8 0.8 0.8 1"/>
  </material>


  <!-- Gemoetry -->
  <link name="base_link">
  </link>

  <link name="chassis">
    <visual>
      <geometry>
        <box size="0.2 0.3 0.08"/>
      </geometry>
      <origin rpy="0 0 0" xyz="0 0 0"/>
      <material name="yellow"/>
    </visual>
  </link>

  <joint name="chassis_joint" type="fixed">
    <parent link="base_link"/>
    <child link="chassis"/>
  </joint>

  <link name="body">
    <visual>
      <geometry>
        <!-- <box size="0.17 0.2 0.07"/> -->
        <mesh filename="package://mobi_rviz/meshes/Housing_v54.stl" scale="0.001 0.001 0.001" />
      </geometry>
      <material name="gray"/>
      <origin rpy="0 0 1.57075" xyz="-0.075 0.1 -0.035"/>
    </visual>
  </link>

  <joint name="body_joint" type="fixed">
    <parent link="chassis"/>
    <child link="body"/>
    <origin rpy="0 0 0" xyz="0 0 0.075"/>
  </joint>

  <link name="top_plate">
    <visual>
      <geometry>
        <!-- <box size="0.15 0.15 0.02"/> -->
        <mesh filename="package://mobi_rviz/meshes/msb15_m-step.stl" scale="0.001 0.001 0.001" />
      </geometry>
      <origin rpy="1.57075 0 0" xyz="0 0 0"/>
    </visual>
  </link>

  <joint name="top_plate_joint" type="fixed">
    <parent link="body"/>
    <child link="top_plate"/>
    <origin rpy="0 0 0" xyz="0 0 0.11"/>
  </joint>


  <!-- Wheels -->

  <link name="front_right_wheel">
    <visual>
      <geometry>
        <cylinder length="0.035" radius="0.0375"/>
      </geometry>
      <material name="blue"/>
    </visual>
  </link>

  <joint name="front_right_wheel_joint" type="continuous">
    <parent link="chassis"/>
    <child link="front_right_wheel"/>
    <origin xyz="0.1275 0.12 -0.025" rpy="1.5707 0 1.5707"/>
    <axis xyz="0 0 -1"/>
  </joint>

  <link name="front_left_wheel">
    <visual>
      <geometry>
        <cylinder length="0.035" radius="0.0375"/>
      </geometry>
      <material name="blue"/>
    </visual>
  </link>

  <joint name="front_left_wheel_joint" type="continuous">
    <parent link="chassis"/>
    <child link="front_left_wheel"/>
    <origin xyz="-0.1275 0.12 -0.025" rpy="-1.5707 0 1.5707"/>
    <axis xyz="0 0 1"/>
  </joint>

  <link name="rear_right_wheel">
    <visual>
      <geometry>
        <cylinder length="0.035" radius="0.0375"/>
      </geometry>
      <material name="blue"/>
    </visual>
  </link>

  <joint name="rear_right_wheel_joint" type="continuous">
    <parent link="chassis"/>
    <child link="rear_right_wheel"/>
    <origin xyz="0.1275 -0.12 -0.025" rpy="1.5707 0 1.5707"/>
    <axis xyz="0 0 -1"/>
  </joint>

  <link name="rear_left_wheel">
    <visual>
      <geometry>
        <cylinder length="0.035" radius="0.0375"/>
      </geometry>
      <material name="blue"/>
    </visual>
  </link>

  <joint name="rear_left_wheel_joint" type="continuous">
    <parent link="chassis"/>
    <child link="rear_left_wheel"/>
    <origin xyz="-0.1275 -0.12 -0.025" rpy="-1.5707 0 1.5707"/>
    <axis xyz="0 0 1"/>
  </joint>

</robot>
